<?xml version="1.0"?>
<robot name="rihkrover" xmlns:xacro="http://www.ros.org/wiki/xacro">

  <material name="blue">
    <color rgba="0 0 0.8 1"/>
  </material>
  <material name="black">
    <color rgba="0 0 0 1"/>
  </material>
  <material name="white">
    <color rgba="1 1 1 1"/>
  </material>

  <link name="base_link">
    <visual>
      <geometry>
        <box size="0.5 0.3 0.15"/>
      </geometry>
      <material name="blue"/>
    </visual>
    <collision>
      <geometry>
        <box size="0.5 0.3 0.15"/>
      </geometry>
    </collision>
    <inertial>
      <mass value="5.0"/>
      <inertia ixx="0.1" ixy="0" ixz="0" iyy="0.1" iyz="0" izz="0.1"/>
    </inertial>
  </link>

  <link name="left_wheel">
    <visual>
      <geometry>
        <cylinder length="0.05" radius="0.1"/>
      </geometry>
      <material name="black"/>
    </visual>
    <collision>
      <geometry>
        <cylinder length="0.05" radius="0.1"/>
      </geometry>
    </collision>
    <inertial>
      <mass value="0.5"/>
      <inertia ixx="0.01" ixy="0" ixz="0" iyy="0.01" iyz="0" izz="0.01"/>
    </inertial>
  </link>

  <link name="right_wheel">
    <visual>
      <geometry>
        <cylinder length="0.05" radius="0.1"/>
      </geometry>
      <material name="black"/>
    </visual>
    <collision>
      <geometry>
        <cylinder length="0.05" radius="0.1"/>
      </geometry>
    </collision>
    <inertial>
      <mass value="0.5"/>
      <inertia ixx="0.01" ixy="0" ixz="0" iyy="0.01" iyz="0" izz="0.01"/>
    </inertial>
  </link>

  <link name="caster_wheel">
    <visual>
      <geometry>
        <sphere radius="0.05"/>
      </geometry>
      <material name="black"/>
    </visual>
    <collision>
      <geometry>
        <sphere radius="0.05"/>
      </geometry>
    </collision>
    <inertial>
      <mass value="0.1"/>
      <inertia ixx="0.01" ixy="0" ixz="0" iyy="0.01" iyz="0" izz="0.01"/>
    </inertial>
  </link>

  <joint name="left_wheel_joint" type="continuous">
    <parent link="base_link"/>
    <child link="left_wheel"/>
    <origin xyz="-0.2 0.175 -0.05" rpy="-1.5708 0 0"/>
    <axis xyz="0 0 1"/>
  </joint>

  <joint name="right_wheel_joint" type="continuous">
    <parent link="base_link"/>
    <child link="right_wheel"/>
    <origin xyz="-0.2 -0.175 -0.05" rpy="-1.5708 0 0"/>
    <axis xyz="0 0 1"/>
  </joint>

  <joint name="caster_wheel_joint" type="fixed">
    <parent link="base_link"/>
    <child link="caster_wheel"/>
    <origin xyz="0.2 0 -0.1"/>
    <axis xyz="0 0 1"/>
  </joint>

  <joint name="lidar_joint" type="fixed">
    <parent link="base_link"/>
    <child link="laser"/>
    <origin xyz="0.3 0.0 0.1" rpy="0 0 0"/> 
  </joint>

  <link name="laser">
    <visual>
      <geometry>
        <cylinder radius="0.05" length="0.05"/>
      </geometry>
      <material name="black"/>
    </visual>
  </link>

  <joint name="camera_joint" type="fixed">
    <parent link="base_link"/>
    <child link="camera_link"/>
    <origin xyz="0.27 0.00 0.08" rpy="0 0 0"/> 
  </joint>

  <link name="camera_link">
    <visual>
      <geometry>
        <box size="0.02 0.05 0.025"/>
      </geometry>
      <material name="blue"/>
    </visual>
  </link>

  <gazebo reference="laser">
    <sensor name="lidar" type="gpu_lidar">
      <always_on>true</always_on>
      <visualize>true</visualize> 
      <update_rate>10</update_rate>
      <topic>/scan</topic>
      <gz_frame_id>laser</gz_frame_id>
      <ray>
        <scan>
          <horizontal>
            <samples>360</samples>
            <resolution>1.0</resolution>
            <min_angle>-2.0944</min_angle>
            <max_angle>2.0944</max_angle>
          </horizontal>
        </scan>
        <range>
          <min>0.15</min>
          <max>10.0</max>
          <resolution>0.015</resolution>
        </range>
      </ray>
    </sensor>
  </gazebo>

  <gazebo reference="camera_link">
    <sensor name="camera" type="camera">
      <always_on>true</always_on>
      <visualize>true</visualize>
      <update_rate>10.0</update_rate>
      <topic>/image_raw</topic>
      <gz_frame_id>camera_link</gz_frame_id>
      <camera>
        <horizontal_fov>1.089</horizontal_fov>
        <image>
          <width>320</width>
          <height>240</height>
        </image>
        <clip>
          <near>0.05</near>
          <far>8.0</far>
        </clip>
      </camera>
    </sensor>
  </gazebo>  

  <gazebo reference="base_link">
    <material>Gazebo/Blue</material>
  </gazebo>

  <gazebo reference="left_wheel">
    <material>Gazebo/Black</material>
    <mu1 value="1.0"/>
    <mu2 value="1.0"/>
  </gazebo>

  <gazebo reference="right_wheel">
    <material>Gazebo/Black</material>
    <mu1 value="1.0"/>
    <mu2 value="1.0"/>
  </gazebo>

  <gazebo reference="caster_wheel">
    <material>Gazebo/Black</material>
    <mu1 value="0.1"/>
    <mu2 value="0.1"/>
  </gazebo>

  <gazebo>
    <plugin filename="ignition-gazebo-diff-drive-system" name="ignition::gazebo::systems::DiffDrive">
      <left_joint>left_wheel_joint</left_joint>
      <right_joint>right_wheel_joint</right_joint>
      <wheel_separation>0.4</wheel_separation>
      <wheel_radius>0.1</wheel_radius>
      <odom_publish_frequency>50</odom_publish_frequency>
      <topic>/cmd_vel</topic>
      <odom_topic>/odom</odom_topic>
      <tf_topic>/tf</tf_topic>
      <frame_id>odom</frame_id>
      <child_frame_id>base_link</child_frame_id>
    </plugin>

    <plugin filename="ignition-gazebo-joint-state-publisher-system" name="ignition::gazebo::systems::JointStatePublisher">
        <update_rate>50</update_rate>
        <joint_name>left_wheel_joint</joint_name>
        <joint_name>right_wheel_joint</joint_name>
        <topic>/joint_states</topic>
    </plugin>
    <plugin filename="ignition-gazebo-sensors-system" name="ignition::gazebo::systems::Sensors">
      <render_engine>ogre</render_engine>
    </plugin>
  </gazebo>
</robot>
